Starting clinical trial data pipeline...
[INFO] Running notebook: q4_exploration.ipynb
[NbConvertApp] Converting notebook q4_exploration.ipynb to notebook
[NbConvertApp] Writing 77087 bytes to q4_exploration.ipynb
[SUCCESS] Completed: q4_exploration.ipynb
[INFO] Running notebook: q5_missing_data.ipynb
[NbConvertApp] Converting notebook q5_missing_data.ipynb to notebook
[NbConvertApp] Writing 85053 bytes to q5_missing_data.ipynb
[SUCCESS] Completed: q5_missing_data.ipynb
[INFO] Running notebook: q6_transformation.ipynb
[NbConvertApp] Converting notebook q6_transformation.ipynb to notebook
[NbConvertApp] Writing 16432 bytes to q6_transformation.ipynb
[SUCCESS] Completed: q6_transformation.ipynb
[INFO] Running notebook: q7_aggregation.ipynb
[NbConvertApp] Converting notebook q7_aggregation.ipynb to notebook
Traceback (most recent call last):
  File "/home/codespace/.local/lib/python3.12/site-packages/jupyter_core/utils/__init__.py", line 154, in wrapped
    asyncio.get_running_loop()
RuntimeError: no running event loop

During handling of the above exception, another exception occurred:

Traceback (most recent call last):
  File "/home/codespace/.local/bin/jupyter-nbconvert", line 8, in <module>
    sys.exit(main())
             ^^^^^^
  File "/home/codespace/.local/lib/python3.12/site-packages/jupyter_core/application.py", line 284, in launch_instance
    super().launch_instance(argv=argv, **kwargs)
  File "/home/codespace/.local/lib/python3.12/site-packages/traitlets/config/application.py", line 1075, in launch_instance
    app.start()
  File "/home/codespace/.local/lib/python3.12/site-packages/nbconvert/nbconvertapp.py", line 420, in start
    self.convert_notebooks()
  File "/home/codespace/.local/lib/python3.12/site-packages/nbconvert/nbconvertapp.py", line 597, in convert_notebooks
    self.convert_single_notebook(notebook_filename)
  File "/home/codespace/.local/lib/python3.12/site-packages/nbconvert/nbconvertapp.py", line 563, in convert_single_notebook
    output, resources = self.export_single_notebook(
                        ^^^^^^^^^^^^^^^^^^^^^^^^^^^^
  File "/home/codespace/.local/lib/python3.12/site-packages/nbconvert/nbconvertapp.py", line 487, in export_single_notebook
    output, resources = self.exporter.from_filename(
                        ^^^^^^^^^^^^^^^^^^^^^^^^^^^^
  File "/home/codespace/.local/lib/python3.12/site-packages/nbconvert/exporters/exporter.py", line 201, in from_filename
    return self.from_file(f, resources=resources, **kw)
           ^^^^^^^^^^^^^^^^^^^^^^^^^^^^^^^^^^^^^^^^^^^^
  File "/home/codespace/.local/lib/python3.12/site-packages/nbconvert/exporters/exporter.py", line 220, in from_file
    return self.from_notebook_node(
           ^^^^^^^^^^^^^^^^^^^^^^^^
  File "/home/codespace/.local/lib/python3.12/site-packages/nbconvert/exporters/notebook.py", line 36, in from_notebook_node
    nb_copy, resources = super().from_notebook_node(nb, resources, **kw)
                         ^^^^^^^^^^^^^^^^^^^^^^^^^^^^^^^^^^^^^^^^^^^^^^^
  File "/home/codespace/.local/lib/python3.12/site-packages/nbconvert/exporters/exporter.py", line 154, in from_notebook_node
    nb_copy, resources = self._preprocess(nb_copy, resources)
                         ^^^^^^^^^^^^^^^^^^^^^^^^^^^^^^^^^^^^
  File "/home/codespace/.local/lib/python3.12/site-packages/nbconvert/exporters/exporter.py", line 353, in _preprocess
    nbc, resc = preprocessor(nbc, resc)
                ^^^^^^^^^^^^^^^^^^^^^^^
  File "/home/codespace/.local/lib/python3.12/site-packages/nbconvert/preprocessors/base.py", line 48, in __call__
    return self.preprocess(nb, resources)
           ^^^^^^^^^^^^^^^^^^^^^^^^^^^^^^
  File "/home/codespace/.local/lib/python3.12/site-packages/nbconvert/preprocessors/execute.py", line 103, in preprocess
    self.preprocess_cell(cell, resources, index)
  File "/home/codespace/.local/lib/python3.12/site-packages/nbconvert/preprocessors/execute.py", line 124, in preprocess_cell
    cell = self.execute_cell(cell, index, store_history=True)
           ^^^^^^^^^^^^^^^^^^^^^^^^^^^^^^^^^^^^^^^^^^^^^^^^^^
  File "/home/codespace/.local/lib/python3.12/site-packages/jupyter_core/utils/__init__.py", line 158, in wrapped
    return loop.run_until_complete(inner)
           ^^^^^^^^^^^^^^^^^^^^^^^^^^^^^^
  File "/usr/local/python/3.12.1/lib/python3.12/asyncio/base_events.py", line 684, in run_until_complete
    return future.result()
           ^^^^^^^^^^^^^^^
  File "/home/codespace/.local/lib/python3.12/site-packages/nbclient/client.py", line 1062, in async_execute_cell
    await self._check_raise_for_error(cell, cell_index, exec_reply)
  File "/home/codespace/.local/lib/python3.12/site-packages/nbclient/client.py", line 918, in _check_raise_for_error
    raise CellExecutionError.from_cell_and_msg(cell, exec_reply_content)
nbclient.exceptions.CellExecutionError: An error occurred while executing the following cell:
------------------
# TODO: Visualization
plot_df = intervention_summary.copy()
plot_df["intervention_group"] = (
    plot_df["intervention_group"].str.strip().str.title()
)
plot_df = (
    plot_df.groupby("intervention_group", as_index=False)
           .mean(numeric_only=True)
           .sort_values("intervention_group")
)
fig, ax1 = plt.subplots(figsize=(8,5))

color1 = "tab:blue"
color2 = "tab:orange"

ax1.set_xlabel("Intervention Group")
ax1.set_ylabel("Mean CVD Rate", color=color1)
ax1.bar(plot_df["intervention_group"], plot_df["mean_cvd_rate"], color=color1, alpha=0.6, label="Mean CVD Rate")
ax1.tick_params(axis="y", labelcolor=color1)

ax2 = ax1.twinx()
ax2.set_ylabel("Mean Adherence (%)", color=color2)
ax2.plot(plot_df["intervention_group"], plot_df["mean_adherence_pct"], color=color2, marker="o", linewidth=2, label="Mean Adherence (%)")
ax2.tick_params(axis="y", labelcolor=color2)

plt.title("Intervention Group Comparison")
plt.xticks(rotation=30, ha="right")
fig.tight_layout()
plt.show()
------------------


[31m---------------------------------------------------------------------------[39m
[31mKeyError[39m                                  Traceback (most recent call last)
[36mFile [39m[32m~/.local/lib/python3.12/site-packages/pandas/core/indexes/base.py:3812[39m, in [36mIndex.get_loc[39m[34m(self, key)[39m
[32m   3811[39m [38;5;28;01mtry[39;00m:
[32m-> [39m[32m3812[39m     [38;5;28;01mreturn[39;00m [38;5;28;43mself[39;49m[43m.[49m[43m_engine[49m[43m.[49m[43mget_loc[49m[43m([49m[43mcasted_key[49m[43m)[49m
[32m   3813[39m [38;5;28;01mexcept[39;00m [38;5;167;01mKeyError[39;00m [38;5;28;01mas[39;00m err:

[36mFile [39m[32mpandas/_libs/index.pyx:167[39m, in [36mpandas._libs.index.IndexEngine.get_loc[39m[34m()[39m

[36mFile [39m[32mpandas/_libs/index.pyx:196[39m, in [36mpandas._libs.index.IndexEngine.get_loc[39m[34m()[39m

[36mFile [39m[32mpandas/_libs/hashtable_class_helper.pxi:7088[39m, in [36mpandas._libs.hashtable.PyObjectHashTable.get_item[39m[34m()[39m

[36mFile [39m[32mpandas/_libs/hashtable_class_helper.pxi:7096[39m, in [36mpandas._libs.hashtable.PyObjectHashTable.get_item[39m[34m()[39m

[31mKeyError[39m: 'intervention_group'

The above exception was the direct cause of the following exception:

[31mKeyError[39m                                  Traceback (most recent call last)
[36mCell[39m[36m [39m[32mIn[7][39m[32m, line 4[39m
[32m      1[39m [38;5;66;03m# TODO: Visualization[39;00m
[32m      2[39m plot_df = intervention_summary.copy()
[32m      3[39m plot_df[[33m"[39m[33mintervention_group[39m[33m"[39m] = (
[32m----> [39m[32m4[39m     [43mplot_df[49m[43m[[49m[33;43m"[39;49m[33;43mintervention_group[39;49m[33;43m"[39;49m[43m][49m.str.strip().str.title()
[32m      5[39m )
[32m      6[39m plot_df = (
[32m      7[39m     plot_df.groupby([33m"[39m[33mintervention_group[39m[33m"[39m, as_index=[38;5;28;01mFalse[39;00m)
[32m      8[39m            .mean(numeric_only=[38;5;28;01mTrue[39;00m)
[32m      9[39m            .sort_values([33m"[39m[33mintervention_group[39m[33m"[39m)
[32m     10[39m )
[32m     11[39m fig, ax1 = plt.subplots(figsize=([32m8[39m,[32m5[39m))

[36mFile [39m[32m~/.local/lib/python3.12/site-packages/pandas/core/frame.py:4113[39m, in [36mDataFrame.__getitem__[39m[34m(self, key)[39m
[32m   4111[39m [38;5;28;01mif[39;00m [38;5;28mself[39m.columns.nlevels > [32m1[39m:
[32m   4112[39m     [38;5;28;01mreturn[39;00m [38;5;28mself[39m._getitem_multilevel(key)
[32m-> [39m[32m4113[39m indexer = [38;5;28;43mself[39;49m[43m.[49m[43mcolumns[49m[43m.[49m[43mget_loc[49m[43m([49m[43mkey[49m[43m)[49m
[32m   4114[39m [38;5;28;01mif[39;00m is_integer(indexer):
[32m   4115[39m     indexer = [indexer]

[36mFile [39m[32m~/.local/lib/python3.12/site-packages/pandas/core/indexes/base.py:3819[39m, in [36mIndex.get_loc[39m[34m(self, key)[39m
[32m   3814[39m     [38;5;28;01mif[39;00m [38;5;28misinstance[39m(casted_key, [38;5;28mslice[39m) [38;5;129;01mor[39;00m (
[32m   3815[39m         [38;5;28misinstance[39m(casted_key, abc.Iterable)
[32m   3816[39m         [38;5;129;01mand[39;00m [38;5;28many[39m([38;5;28misinstance[39m(x, [38;5;28mslice[39m) [38;5;28;01mfor[39;00m x [38;5;129;01min[39;00m casted_key)
[32m   3817[39m     ):
[32m   3818[39m         [38;5;28;01mraise[39;00m InvalidIndexError(key)
[32m-> [39m[32m3819[39m     [38;5;28;01mraise[39;00m [38;5;167;01mKeyError[39;00m(key) [38;5;28;01mfrom[39;00m[38;5;250m [39m[34;01merr[39;00m
[32m   3820[39m [38;5;28;01mexcept[39;00m [38;5;167;01mTypeError[39;00m:
[32m   3821[39m     [38;5;66;03m# If we have a listlike key, _check_indexing_error will raise[39;00m
[32m   3822[39m     [38;5;66;03m#  InvalidIndexError. Otherwise we fall through and re-raise[39;00m
[32m   3823[39m     [38;5;66;03m#  the TypeError.[39;00m
[32m   3824[39m     [38;5;28mself[39m._check_indexing_error(key)

[31mKeyError[39m: 'intervention_group'

[ERROR] Execution failed for q7_aggregation.ipynb. Stopping pipeline.
